<?xml version="1.0" ?>
<!-- =================================================================================== -->
<!-- |    This document was autogenerated by xacro from separable_jaws.xacro           | -->
<!-- |    EDITING THIS FILE BY HAND IS NOT RECOMMENDED                                 | -->
<!-- =================================================================================== -->
<robot name="car">
  <material name="Red">
    <color rgba="0.8 0.0 0.0 1.0"/>
  </material>
  <material name="Green">
    <color rgba="0.0 0.8 0.0 1.0"/>
  </material>
  <material name="Blue">
    <color rgba="0.0 0.0 0.8 1.0"/>
  </material>
  <material name="White">
    <color rgba="1.0 1.0 1.0 1.0"/>
  </material>
  <material name="Grey">
    <color rgba="0.39215686274509803 0.39215686274509803 0.39215686274509803 1.0"/>
  </material>
  <material name="Black">
    <color rgba="0.0 0.0 0.0 1.0"/>
  </material>
  <material name="Orange">
    <color rgba="1.0 0.4235294117647059 0.0392156862745098 1.0"/>
  </material>
  <!-- robot definition -->
  <link name="base_link">
    </link>
  <link name="chassis">
    <inertial>
      <origin rpy="0 0 0" xyz="0 0 0"/>
      <mass value="1"/>
      <inertia ixx="0.02416666666666667" ixy="0.0" ixz="0.0" iyy="0.08666666666666667" iyz="0.0" izz="0.10416666666666666"/>
    </inertial>
    <visual>
      <origin rpy="0 0 0" xyz="0 0 0"/>
      <geometry>
        <box size="1 0.5 0.2"/>
      </geometry>
      <material name="Red"/>
    </visual>
    <collision>
      <origin rpy="0 0 0" xyz="0 0 0"/>
      <geometry>
        <box size="1 0.5 0.2"/>
      </geometry>
    </collision>
  </link>
  <gazebo reference="chassis">
    <material>Gazebo/Red</material>
  </gazebo>
  <link name="front_left_wheel">
    <inertial>
      <origin rpy="1.5707963267948966 0 0" xyz="0 0 0"/>
      <mass value="1.0"/>
      <inertia ixx="0.023333333333333334" ixy="0.0" ixz="0.0" iyy="0.023333333333333334" iyz="0.0" izz="0.045"/>
    </inertial>
    <visual>
      <origin rpy="1.5707963267948966 0 0" xyz="0 0 0"/>
      <geometry>
        <cylinder length="0.1" radius="0.3"/>
      </geometry>
      <material name="Black"/>
    </visual>
    <collision>
      <origin rpy="1.5707963267948966 0 0" xyz="0 0 0"/>
      <geometry>
        <cylinder length="0.1" radius="0.3"/>
      </geometry>
    </collision>
  </link>
  <gazebo reference="front_left_wheel">
    <material>Gazebo/Black</material>
  </gazebo>
  <link name="front_right_wheel">
    <inertial>
      <origin rpy="1.5707963267948966 0 0" xyz="0 0 0"/>
      <mass value="1.0"/>
      <inertia ixx="0.023333333333333334" ixy="0.0" ixz="0.0" iyy="0.023333333333333334" iyz="0.0" izz="0.045"/>
    </inertial>
    <visual>
      <origin rpy="1.5707963267948966 0 0" xyz="0 0 0"/>
      <geometry>
        <cylinder length="0.1" radius="0.3"/>
      </geometry>
      <material name="Black"/>
    </visual>
    <collision>
      <origin rpy="1.5707963267948966 0 0" xyz="0 0 0"/>
      <geometry>
        <cylinder length="0.1" radius="0.3"/>
      </geometry>
    </collision>
  </link>
  <gazebo reference="front_right_wheel">
    <material>Gazebo/Black</material>
  </gazebo>
  <link name="rear_left_wheel">
    <inertial>
      <origin rpy="1.5707963267948966 0 0" xyz="0 0 0"/>
      <mass value="1.0"/>
      <inertia ixx="0.023333333333333334" ixy="0.0" ixz="0.0" iyy="0.023333333333333334" iyz="0.0" izz="0.045"/>
    </inertial>
    <visual>
      <origin rpy="1.5707963267948966 0 0" xyz="0 0 0"/>
      <geometry>
        <cylinder length="0.1" radius="0.3"/>
      </geometry>
      <material name="Black"/>
    </visual>
    <collision>
      <origin rpy="1.5707963267948966 0 0" xyz="0 0 0"/>
      <geometry>
        <cylinder length="0.1" radius="0.3"/>
      </geometry>
    </collision>
  </link>
  <gazebo reference="rear_left_wheel">
    <material>Gazebo/Black</material>
  </gazebo>
  <link name="rear_right_wheel">
    <inertial>
      <origin rpy="1.5707963267948966 0 0" xyz="0 0 0"/>
      <mass value="1.0"/>
      <inertia ixx="0.023333333333333334" ixy="0.0" ixz="0.0" iyy="0.023333333333333334" iyz="0.0" izz="0.045"/>
    </inertial>
    <visual>
      <origin rpy="1.5707963267948966 0 0" xyz="0 0 0"/>
      <geometry>
        <cylinder length="0.1" radius="0.3"/>
      </geometry>
      <material name="Black"/>
    </visual>
    <collision>
      <origin rpy="1.5707963267948966 0 0" xyz="0 0 0"/>
      <geometry>
        <cylinder length="0.1" radius="0.3"/>
      </geometry>
    </collision>
  </link>
  <gazebo reference="rear_right_wheel">
    <material>Gazebo/Black</material>
  </gazebo>
  <joint name="base_link" type="fixed">
    <parent link="base_link"/>
    <child link="chassis"/>
    <origin rpy="0 0 0" xyz="0 0 0.3"/>
  </joint>
  <joint name="front_left_wheel_joint" type="continuous">
    <parent link="chassis"/>
    <child link="front_left_wheel"/>
    <origin rpy="0 0 0" xyz="0.4 -0.3 0"/>
    <axis xyz="0 1 0"/>
  </joint>
  <joint name="front_right_wheel_joint" type="continuous">
    <parent link="chassis"/>
    <child link="front_right_wheel"/>
    <origin rpy="0 0 0" xyz="0.4 0.3 0"/>
    <axis xyz="0 1 0"/>
  </joint>
  <joint name="rear_left_wheel_joint" type="continuous">
    <parent link="chassis"/>
    <child link="rear_left_wheel"/>
    <origin rpy="0 0 0" xyz="-0.4 -0.3 0"/>
    <axis xyz="0 1 0"/>
  </joint>
  <joint name="rear_right_wheel_joint" type="continuous">
    <parent link="chassis"/>
    <child link="rear_right_wheel"/>
    <origin rpy="0 0 0" xyz="-0.4 0.3 0"/>
    <axis xyz="0 1 0"/>
  </joint>
</robot>
